Traceback (most recent call last):
  File "/home/hugo/conda/envs/hugo/lib/python3.8/site-packages/jupyter_cache/executors/utils.py", line 51, in single_nb_execution
    executenb(
  File "/home/hugo/conda/envs/hugo/lib/python3.8/site-packages/nbclient/client.py", line 1204, in execute
    return NotebookClient(nb=nb, resources=resources, km=km, **kwargs).execute()
  File "/home/hugo/conda/envs/hugo/lib/python3.8/site-packages/nbclient/util.py", line 84, in wrapped
    return just_run(coro(*args, **kwargs))
  File "/home/hugo/conda/envs/hugo/lib/python3.8/site-packages/nbclient/util.py", line 62, in just_run
    return loop.run_until_complete(coro)
  File "/home/hugo/conda/envs/hugo/lib/python3.8/asyncio/base_events.py", line 616, in run_until_complete
    return future.result()
  File "/home/hugo/conda/envs/hugo/lib/python3.8/site-packages/nbclient/client.py", line 663, in async_execute
    await self.async_execute_cell(
  File "/home/hugo/conda/envs/hugo/lib/python3.8/site-packages/nbclient/client.py", line 965, in async_execute_cell
    await self._check_raise_for_error(cell, cell_index, exec_reply)
  File "/home/hugo/conda/envs/hugo/lib/python3.8/site-packages/nbclient/client.py", line 862, in _check_raise_for_error
    raise CellExecutionError.from_cell_and_msg(cell, exec_reply_content)
nbclient.exceptions.CellExecutionError: An error occurred while executing the following cell:
------------------
curr_model.load_model('./checkpoints/img_audio_221128/w_ep-00195_l-0.0908.pth')
------------------

[0;31m---------------------------------------------------------------------------[0m
[0;31mFileNotFoundError[0m                         Traceback (most recent call last)
Cell [0;32mIn[7], line 1[0m
[0;32m----> 1[0m [43mcurr_model[49m[38;5;241;43m.[39;49m[43mload_model[49m[43m([49m[38;5;124;43m'[39;49m[38;5;124;43m./checkpoints/img_audio_221128/w_ep-00195_l-0.0908.pth[39;49m[38;5;124;43m'[39;49m[43m)[49m

File [0;32m~/tutorial/book/examples-zsl/model_manager.py:99[0m, in [0;36mModelManager.load_model[0;34m(self, weight_path)[0m
[1;32m     98[0m [38;5;28;01mdef[39;00m [38;5;21mload_model[39m([38;5;28mself[39m, weight_path):
[0;32m---> 99[0m     state_dict [38;5;241m=[39m [43mtorch[49m[38;5;241;43m.[39;49m[43mload[49m[43m([49m[43mweight_path[49m[43m,[49m[43m [49m[43mmap_location[49m[38;5;241;43m=[39;49m[38;5;28;43mself[39;49m[38;5;241;43m.[39;49m[43mdevice[49m[43m)[49m
[1;32m    100[0m     [38;5;28;01mif[39;00m torch[38;5;241m.[39mcuda[38;5;241m.[39mdevice_count() [38;5;241m>[39m [38;5;241m1[39m:
[1;32m    101[0m         [38;5;28mself[39m[38;5;241m.[39mmodel[38;5;241m.[39mload_state_dict(state_dict)

File [0;32m~/conda/envs/hugo/lib/python3.8/site-packages/torch/serialization.py:771[0m, in [0;36mload[0;34m(f, map_location, pickle_module, weights_only, **pickle_load_args)[0m
[1;32m    768[0m [38;5;28;01mif[39;00m [38;5;124m'[39m[38;5;124mencoding[39m[38;5;124m'[39m [38;5;129;01mnot[39;00m [38;5;129;01min[39;00m pickle_load_args[38;5;241m.[39mkeys():
[1;32m    769[0m     pickle_load_args[[38;5;124m'[39m[38;5;124mencoding[39m[38;5;124m'[39m] [38;5;241m=[39m [38;5;124m'[39m[38;5;124mutf-8[39m[38;5;124m'[39m
[0;32m--> 771[0m [38;5;28;01mwith[39;00m [43m_open_file_like[49m[43m([49m[43mf[49m[43m,[49m[43m [49m[38;5;124;43m'[39;49m[38;5;124;43mrb[39;49m[38;5;124;43m'[39;49m[43m)[49m [38;5;28;01mas[39;00m opened_file:
[1;32m    772[0m     [38;5;28;01mif[39;00m _is_zipfile(opened_file):
[1;32m    773[0m         [38;5;66;03m# The zipfile reader is going to advance the current file position.[39;00m
[1;32m    774[0m         [38;5;66;03m# If we want to actually tail call to torch.jit.load, we need to[39;00m
[1;32m    775[0m         [38;5;66;03m# reset back to the original position.[39;00m
[1;32m    776[0m         orig_position [38;5;241m=[39m opened_file[38;5;241m.[39mtell()

File [0;32m~/conda/envs/hugo/lib/python3.8/site-packages/torch/serialization.py:270[0m, in [0;36m_open_file_like[0;34m(name_or_buffer, mode)[0m
[1;32m    268[0m [38;5;28;01mdef[39;00m [38;5;21m_open_file_like[39m(name_or_buffer, mode):
[1;32m    269[0m     [38;5;28;01mif[39;00m _is_path(name_or_buffer):
[0;32m--> 270[0m         [38;5;28;01mreturn[39;00m [43m_open_file[49m[43m([49m[43mname_or_buffer[49m[43m,[49m[43m [49m[43mmode[49m[43m)[49m
[1;32m    271[0m     [38;5;28;01melse[39;00m:
[1;32m    272[0m         [38;5;28;01mif[39;00m [38;5;124m'[39m[38;5;124mw[39m[38;5;124m'[39m [38;5;129;01min[39;00m mode:

File [0;32m~/conda/envs/hugo/lib/python3.8/site-packages/torch/serialization.py:251[0m, in [0;36m_open_file.__init__[0;34m(self, name, mode)[0m
[1;32m    250[0m [38;5;28;01mdef[39;00m [38;5;21m__init__[39m([38;5;28mself[39m, name, mode):
[0;32m--> 251[0m     [38;5;28msuper[39m(_open_file, [38;5;28mself[39m)[38;5;241m.[39m[38;5;21m__init__[39m([38;5;28;43mopen[39;49m[43m([49m[43mname[49m[43m,[49m[43m [49m[43mmode[49m[43m)[49m)

[0;31mFileNotFoundError[0m: [Errno 2] No such file or directory: './checkpoints/img_audio_221128/w_ep-00195_l-0.0908.pth'
FileNotFoundError: [Errno 2] No such file or directory: './checkpoints/img_audio_221128/w_ep-00195_l-0.0908.pth'

